<?xml version="1.0"?>
<robot name="gwam">

  <!-- BASE_LINK (RED) -->
  <link name="base_link">
    <visual>
       <origin xyz="0 0 0" rpy="0 0 0" />
       <geometry>
	 <mesh filename="robot/guardian_description/meshes/chassis/v5/chassisV5_l.stl"/>
       </geometry>
	<material name="red">
	  <color rgba="1.0 0 0 1"/>
 	</material>
    </visual>
  </link>

  <!-- LEFT TRACK (BLACK) -->
  <link name="left_track">
    <visual>
        <origin xyz="0 0 0" rpy="0 0 0" /> 
        <geometry>
	 <mesh filename="robot/guardian_description/meshes/others/v5/trackV5_l.stl"/>
        </geometry>
	<material name="black">
  		<color rgba="0.1 0.1 0.1 1"/>
      	</material>
    </visual>
  </link>
  <joint name="joint_left_track" type="fixed">
    <parent link="base_link"/>
    <child link="left_track"/>
    <origin xyz="0.0 0.0 0.0" rpy="0 0 0" /> 
  </joint>
  <!-- RIGHT TRACK (BLACK) -->
  <link name="right_track">
    <visual>
       <origin xyz="0 0 0" rpy="0 0 0" /> 
       <geometry>
	 <mesh filename="robot/guardian_description/meshes/others/v5/trackV5_l.stl"/>
       </geometry>
	<material name="black">
		<color rgba="0.1 0.1 0.1 1"/>
      	</material>
    </visual>
  </link>
  <joint name="joint_right_track" type="fixed">
    <parent link="base_link"/>
    <child link="right_track"/>
    <origin xyz="0.0 0.0 0.0" rpy="0 0 3.1415926535" /> 
  </joint>

<!-- WHISKER ARM -->
  <link name="whiskerArmBase">
    <visual>
       <origin xyz="0 0 0" rpy="0 0 1.57" /> 
       <geometry>
	 <mesh filename="robot/guardian_description/meshes/whiskers/pa10link1.3ds"/>
       </geometry>
	<material name="black">
		<color rgba="0.1 0.1 0.1 1"/>
      	</material>
    </visual>
  </link>

  <joint name="whiskerArmBase_joint" type="fixed">
    <parent link="base_link"/>
    <child link="whiskerArmBase"/>
    <origin xyz="-0. -0.23 0.32" rpy="1.57 1.57 0" /> 
  </joint>

  <link name="whiskerArmLink1">
    <visual>
       <origin xyz="0 0 0" rpy="0 1.57 0" /> 
       <geometry>
	 <mesh filename="robot/guardian_description/meshes/whiskers/pa10link2.3ds"/>
       </geometry>
	<material name="white">
		<color rgba="1 1 1 1"/>
      	</material>
    </visual>
  </link>

  <joint name="whiskerArm_joint1" type="fixed">
    <parent link="whiskerArmBase"/>
    <child link="whiskerArmLink1"/>
    <origin xyz="-0 -0 0" rpy="-2.15 0 0" /> 
  </joint>

  <link name="whiskerArmLink2">
    <visual>
       <origin xyz="0 0 0" rpy="1.57 0 0" /> 
       <geometry>
	 <mesh filename="robot/guardian_description/meshes/whiskers/pa10link3.3ds"/>
       </geometry>
	<material name="black">
      	</material>
    </visual>
  </link>

  <joint name="whiskerArm_joint2" type="fixed">
    <parent link="whiskerArmLink1"/>
    <child link="whiskerArmLink2"/>
    <origin xyz="-0 -0.175 0" rpy="0 0 0" /> 
  </joint>

  <link name="whiskerArmLink3">
    <visual>
       <origin xyz="0 0 0" rpy="0 0 0" /> 
       <geometry>
	 <mesh filename="robot/guardian_description/meshes/whiskers/pa10link4.3ds"/>
       </geometry>
	<material name="black">
      	</material>
    </visual>
  </link>

  <joint name="whiskerArm_joint3" type="fixed">
    <parent link="whiskerArmLink2"/>
    <child link="whiskerArmLink3"/>
    <origin xyz="-0 -0 0" rpy="0 0 0.6" /> 
  </joint>


  <link name="whiskerArmLink4">
    <visual>
       <origin xyz="0 0 0" rpy="0 0 0" /> 
       <geometry>
	 <mesh filename="robot/guardian_description/meshes/whiskers/end_effector.stl"/>
       </geometry>
	<material name="white">
      	</material>
    </visual>
  </link>

  <joint name="whiskerArm_joint4" type="fixed">
    <parent link="whiskerArmLink3"/>
    <child link="whiskerArmLink4"/>
    <origin xyz="-0 -0 0" rpy="0 0 0" /> 
  </joint>

<!--ARM WHISKERS -->

  <link name="whisker1">
    <visual>
       <origin xyz="0 0 0" rpy="0 -1.57 3.14" /> 
       <geometry>
	 <mesh filename="robot/guardian_description/meshes/whiskers/shortWhisker3X.3ds"/>
       </geometry>
	<material name="yellow">
		<color rgba="1 1 0 1"/>
      	</material>
    </visual>
  </link>

  <joint name="whisker1_joint" type="fixed">
    <parent link="whiskerArmLink4"/>
    <child link="whisker1"/>
    <origin xyz="-0.047 -0.115 0" rpy="0 0 -1.14" /> 
  </joint>


 <link name="whisker4">
    <visual>
       <origin xyz="0 0 0" rpy="0 -1.57 3.14" /> 
       <geometry>
	 <mesh filename="robot/guardian_description/meshes/whiskers/shortWhisker3X.3ds"/>
       </geometry>
	<material name="yellow">
		<color rgba="1 1 0 1"/>
      	</material>
    </visual>
  </link>

  <joint name="whisker4_joint" type="fixed">
    <parent link="whiskerArmLink4"/>
    <child link="whisker4"/>
    <origin xyz="-0.035 -0.115 -0.035" rpy="0.7 -0.2 -1.14" /> 
  </joint>

 

 <link name="whisker7">
    <visual>
       <origin xyz="0 0 0" rpy="0 -1.57 3.14" /> 
       <geometry>
	 <mesh filename="robot/guardian_description/meshes/whiskers/shortWhisker3X.3ds"/>
       </geometry>
	<material name="yellow">
		<color rgba="1 1 0 1"/>
      	</material>
    </visual>
  </link>

  <joint name="whisker7_joint" type="fixed">
    <parent link="whiskerArmLink4"/>
    <child link="whisker7"/>
    <origin xyz="-0.035 -0.115 0.035" rpy="-0.7 0.2 -1.14" /> 
  </joint>


 <link name="whisker8">
    <visual>
       <origin xyz="0 0 0" rpy="0 -1.57 3.14" /> 
       <geometry>
	 <mesh filename="robot/guardian_description/meshes/whiskers/shortWhisker3X.3ds"/>
       </geometry>
	<material name="yellow">
		<color rgba="1 1 0 1"/>
      	</material>
    </visual>
  </link>

  <joint name="whisker8_joint" type="fixed">
    <parent link="whiskerArmLink4"/>
    <child link="whisker8"/>
    <origin xyz="-0.015 -0.115 0.047" rpy="-1.4 0.4 -1.14" /> 
  </joint>

 <link name="whisker9">
    <visual>
       <origin xyz="0 0 0" rpy="0 -1.57 3.14" /> 
       <geometry>
	 <mesh filename="robot/guardian_description/meshes/whiskers/shortWhisker3X.3ds"/>
       </geometry>
	<material name="yellow">
		<color rgba="1 1 0 1"/>
      	</material>
    </visual>
  </link>

  <joint name="whisker9_joint" type="fixed">
    <parent link="whiskerArmLink4"/>
    <child link="whisker9"/>
    <origin xyz="-0.015 -0.115 -0.047" rpy="1.4 -0.4 -1.14" /> 
  </joint>
  



<!-- 
  <!-- WHISKER -- >
  <link name="whisker1">
    <visual>
       <origin xyz="0 0 0" rpy="0 0 0" /> 
       <geometry>
	 <mesh filename="robot/guardian_description/meshes/whiskers/whisker.3ds"/>
       </geometry>
	<material name="brown">
		<color rgba="0.3 0.1 0.1 1"/>
      	</material>
    </visual>
  </link>

  <joint name="whisker1_joint" type="fixed">
    <parent link="base_link"/>
    <child link="whisker1"/>
    <origin xyz="-0.325 0.2 0.35" rpy="0 0 0" /> 
  </joint>

  <!-- WHISKER2 -- >
  <link name="whisker2">
    <visual>
       <origin xyz="0 0 0" rpy="0 0 0" /> 
       <geometry>
	 <mesh filename="robot/guardian_description/meshes/whiskers/whisker.3ds"/>
       </geometry>
	<material name="brown" />
    </visual>
  </link>

  <joint name="whisker2_joint" type="fixed">
    <parent link="base_link"/>
    <child link="whisker2"/>
    <origin xyz="-0.15 0.2 0.35" rpy="0 0 0" /> 
  </joint>


  <!-- WHISKER3 -- >
  <link name="whisker3">
    <visual>
       <origin xyz="0 0 0" rpy="0 0 0" /> 
       <geometry>
	 <mesh filename="robot/guardian_description/meshes/whiskers/whisker.3ds"/>
       </geometry>
	<material name="brown" />
    </visual>
  </link>

  <joint name="whisker3_joint" type="fixed">
    <parent link="base_link"/>
    <child link="whisker3"/>
    <origin xyz="0.05 0.2 0.35" rpy="0 0 0" /> 
  </joint>

  <!-- WHISKER4 -- >
  <link name="whisker4">
    <visual>
       <origin xyz="0 0 0" rpy="0 0 0" /> 
       <geometry>
	 <mesh filename="robot/guardian_description/meshes/whiskers/whisker.3ds"/>
       </geometry>
	<material name="brown" />
    </visual>
  </link>

  <joint name="whisker4_joint" type="fixed">
    <parent link="base_link"/>
    <child link="whisker4"/>
    <origin xyz="0.25 0.2 0.35" rpy="0 0 0" /> 
  </joint>

  <!-- WHISKER LEFT 1 -- >
  <link name="whiskerl1">
    <visual>
       <origin xyz="0 0 0" rpy="0 0 3.14" /> 
       <geometry>
	 <mesh filename="robot/guardian_description/meshes/whiskers/whiskerBezier2.3ds"/>
       </geometry>
	<material name="brown" />
    </visual>
  </link>

  <joint name="whiskerl1_joint" type="fixed">
    <parent link="base_link"/>
    <child link="whiskerl1"/>
    <origin xyz="-0.325 -0.2 0.35" rpy="0 0 0" /> 
  </joint>

  <!-- WHISKER LEFT 2 -- >
  <link name="whiskerl2">
    <visual>
       <origin xyz="0 0 0" rpy="0 0 3.14" /> 
       <geometry>
	 <mesh filename="robot/guardian_description/meshes/whiskers/whiskerBezier2.3ds"/>
       </geometry>
	<material name="brown" />
    </visual>
  </link>

  <joint name="whiskerl2_joint" type="fixed">
    <parent link="base_link"/>
    <child link="whiskerl2"/>
    <origin xyz="-0.15 -0.2 0.35" rpy="0 0 0" /> 
  </joint>


  <!-- WHISKER LEFT 3 -- >
  <link name="whiskerl3">
    <visual>
       <origin xyz="0 0 0" rpy="0 0 3.14" /> 
       <geometry>
	 <mesh filename="robot/guardian_description/meshes/whiskers/whiskerBezier2.3ds"/>
       </geometry>
	<material name="brown" />
    </visual>
  </link>

  <joint name="whiskerl3_joint" type="fixed">
    <parent link="base_link"/>
    <child link="whiskerl3"/>
    <origin xyz="0.05 -0.2 0.35" rpy="0 0 0" /> 
  </joint>

  <!-- WHISKER LEFT 4 -- >
  <link name="whiskerl4">
    <visual>
       <origin xyz="0 0 0" rpy="0 0 3.14" /> 
       <geometry>
	 <mesh filename="robot/guardian_description/meshes/whiskers/whiskerBezier2.3ds"/>
       </geometry>
	<material name="brown" />
    </visual>
  </link>

  <joint name="whiskerl4_joint" type="fixed">
    <parent link="base_link"/>
    <child link="whiskerl4"/>
    <origin xyz="0.25 -0.2 0.35" rpy="0 0 0" /> 
  </joint>

  <!-- WHISKER FRONT 1 -- >
  <link name="whiskerf1"> <!-- el mas rapido de los whiskers -- >
    <visual>
       <origin xyz="0 0 0" rpy="0 0 -1.57" /> 
       <geometry>
	 <mesh filename="robot/guardian_description/meshes/whiskers/longwhisker.3ds"/>
       </geometry>
	<material name="brown" />
    </visual>
  </link>

  <joint name="whiskerf1_joint" type="fixed">
    <parent link="base_link"/>
    <child link="whiskerf1"/>
    <origin xyz="0.30 -0.2 0.35" rpy="0 0 0" /> 
  </joint>

  <!-- WHISKER FRONT 2 -- >
  <link name="whiskerf2">
    <visual>
       <origin xyz="0 0 0" rpy="0 0 -1.57" /> 
       <geometry>
	 <mesh filename="robot/guardian_description/meshes/whiskers/longwhisker.3ds"/>
       </geometry>
	<material name="brown" />
    </visual>
  </link>

  <joint name="whiskerf2_joint" type="fixed">
    <parent link="base_link"/>
    <child link="whiskerf2"/>
    <origin xyz="0.30 0.2 0.35" rpy="0 0 0" /> 
  </joint>
-->



  <!-- BACK LEFT WHEEL (GREY) -->
  <link name="back_left_wheel">
    <visual>
       <origin xyz="0 0 0" rpy="0 0 3.1416" /> 
       <geometry>
	 <mesh filename="robot/guardian_description/meshes/wheel.stl"/>
       </geometry>
	<material name="grey">
		<color rgba="0.3 0.3 0.3 1"/>
      	</material>
    </visual>
  </link>

  <joint name="w0" type="continuous">
    <parent link="base_link"/>
    <child link="back_left_wheel"/>
    <origin xyz="-0.30 0.265 0" rpy="0 0 0" /> 
    <axis xyz="0 1 0" rpy="0 0 0" />
    <limit effort="100" velocity="100"/>
    <joint_properties damping="0.0" friction="0.0"/>
  </joint>

  <!-- BACK RIGHT WHEEL (BLACK) -->
  <link name="back_right_wheel">
    <visual>
       <origin xyz="0 0 0" rpy="0 0 0" /> 
       <geometry>
	 <mesh filename="robot/guardian_description/meshes/wheel.stl"/>
       </geometry>
	<material name="grey">
		<color rgba="0.3 0.3 0.3 1"/>
      	</material>
    </visual>
  </link>
  
  <joint name="w1" type="continuous">
    <parent link="base_link"/>
    <child link="back_right_wheel"/>
    <origin xyz="-0.30 -0.265 0" rpy="0 0 0" />
    <axis xyz="0 1 0" />
    <limit effort="100" velocity="100"/>
    <joint_properties damping="0.0" friction="0.0"/>
  </joint>

  <!-- FRONT LEFT WHEEL (GREY) -->
  <link name="front_left_wheel">
    <visual>
       <origin xyz="0 0 0" rpy="0 0 3.1416" /> 
       <geometry>
	 <mesh filename="robot/guardian_description/meshes/wheel.stl"/>
       </geometry>
	<material name="grey">
		<color rgba="0.3 0.3 0.3 1"/>
      	</material>
    </visual>
  </link>

  <joint name="w2" type="continuous">
    <parent link="base_link"/>
    <child link="front_left_wheel"/>
    <origin xyz="0.30 0.265 0" rpy="0 0 0" />
    <axis xyz="0 1 0" />
    <limit effort="100" velocity="100"/>
    <joint_properties damping="0.0" friction="0.0"/>
  </joint>

  <!-- FRONT RIGHT WHEEL (GREY) -->
  <link name="front_right_wheel">
    <visual>
       <origin xyz="0 0 0" rpy="0 0 0" /> 
       <geometry>
	 <mesh filename="robot/guardian_description/meshes/wheel.stl"/>
       </geometry>
	<material name="grey">
		<color rgba="0.3 0.3 0.3 1"/>
      	</material>
    </visual>
  </link>

  <joint name="w3" type="continuous">
    <parent link="base_link"/>
    <child link="front_right_wheel"/>
    <origin xyz="0.30 -0.265 0" rpy="0 0 0" />
    <axis xyz="0 1 0" />
    <limit effort="100" velocity="100"/>
    <joint_properties damping="0.0" friction="0.0"/>
  </joint>



  <!-- WAM ARM -->
 
  <link name="wam_link1">
    <visual>
      <origin rpy="0 0 0" xyz="0.0 0.0 0.0"/>
      <geometry name="wam_link1_visual">
        <mesh filename="robot/iri_wam/iri_wam_description/mesh/wam1.stl" scale="1.0 1.0 1.0"/>
      </geometry>
      <material name="White">
        <color rgba="1.0 1.0 1.0 1.0"/>
      </material>
    </visual>
  </link>
  <joint name="j1_joint" type="revolute">
    <parent link="base_link"/>
    <child link="wam_link1"/>
    <origin xyz="0.125 0 0.55" rpy="0 0 0" />
    <axis xyz="0 0 1"/>
    <limit effort="30" lower="-2.6" upper="2.6" velocity="2.0"/>
    <dynamics damping="100"/>
  </joint>
  <link name="wam_link2">
    <visual>
      <origin rpy="0 0 0" xyz="0.0 0.0 0.0"/>
      <geometry name="wam_link2_visual">
        <mesh filename="robot/iri_wam/iri_wam_description/mesh/wam2.stl" scale="1.0 1.0 1.0"/>
      </geometry>
      <material name="Grey">
        <color rgba="0.3 0.3 0.3 1.0"/>
      </material>
    </visual>
  </link>
  <joint name="j2_joint" type="revolute">
    <parent link="wam_link1"/>
    <child link="wam_link2"/>
    <origin rpy="0 0 0" xyz="0.0 0.0 0.0"/>
    <axis xyz="0 1 0"/>
    <limit effort="30" lower="-2.0" upper="2.0" velocity="2.0"/>
    <dynamics damping="100"/>
  </joint>
  <link name="wam_link3">
    <visual>
      <origin rpy="0 0 0" xyz="0.0 0.0 0.0"/>
      <geometry name="wam_link3_visual">
        <mesh filename="robot/iri_wam/iri_wam_description/mesh/wam3.stl" scale="1.0 1.0 1.0"/>
      </geometry>
      <material name="Grey">
        <color rgba="0.3 0.3 0.3 1.0"/>
      </material>
    </visual>
  </link>
  <joint name="j3_joint" type="revolute">
    <parent link="wam_link2"/>
    <child link="wam_link3"/>
    <origin rpy="0 0 0" xyz="0.0 0.0 0.0"/>
    <axis xyz="0 0 1"/>
    <limit effort="30" lower="-2.8" upper="2.8" velocity="2.0"/>
    <dynamics damping="100"/>
  </joint>
  <link name="wam_link4">
    <visual>
      <origin rpy="0 0 0" xyz="0.0 0.0 0.0"/>
      <geometry name="wam_link4_visual">
        <mesh filename="robot/iri_wam/iri_wam_description/mesh/wam4.stl" scale="1.0 1.0 1.0"/>
      </geometry>
      <material name="Grey">
        <color rgba="0.3 0.3 0.3 1.0"/>
      </material>
    </visual>
  </link>
  <joint name="j4_joint" type="revolute">
    <parent link="wam_link3"/>
    <child link="wam_link4"/>
    <origin rpy="-1.57079632679 0 0" xyz="0.045 0.0 0.55"/>
    <axis xyz="0 0 1"/>
    <limit effort="35" lower="-0.9" upper="2.8" velocity="2.0"/>
    <dynamics damping="100"/>
  </joint>
  <link name="wam_link5">
    <visual>
      <origin rpy="0 0 0" xyz="0.0 0.0 0.0"/>
      <geometry name="wam_link5_visual">
        <mesh filename="robot/iri_wam/iri_wam_description/mesh/wam5.stl" scale="1.0 1.0 1.0"/>
      </geometry>
      <material name="Grey">
        <color rgba="0.3 0.3 0.3 1.0"/>
      </material>
    </visual>
  </link>
  <joint name="j5_joint" type="revolute">
    <parent link="wam_link4"/>
    <child link="wam_link5"/>
    <origin rpy="1.57079632679 0 0" xyz="-0.045 -0.3 0.0"/>
    <axis xyz="0 0 1"/>
    <limit effort="30" lower="-4.8" upper="1.3" velocity="2.0"/>
    <dynamics damping="100"/>
  </joint>
  <link name="wam_link6">
    <visual>
      <origin rpy="0 0 0" xyz="0.0 0.0 0.0"/>
      <geometry name="wam_link6_visual">
        <mesh filename="robot/iri_wam/iri_wam_description/mesh/wam6.stl" scale="1.0 1.0 1.0"/>
      </geometry>
      <material name="Grey">
        <color rgba="0.3 0.3 0.3 1.0"/>
      </material>
    </visual>
  </link>
  <joint name="j6_joint" type="revolute">
    <parent link="wam_link5"/>
    <child link="wam_link6"/>
    <origin rpy="-1.57079632679 0 0" xyz="0.0 0.0 0.0"/>
    <axis xyz="0 0 1"/>
    <limit effort="30" lower="-1.6" upper="1.6" velocity="2.0"/>
    <dynamics damping="100"/>
  </joint>
  <link name="wam_link7">
    <visual>
      <origin rpy="0 0 0" xyz="0.0 0.0 0.0"/>
      <geometry name="wam_link7_visual">
        <mesh filename="robot/iri_wam/iri_wam_description/mesh/wam7.stl" scale="1.0 1.0 1.0"/>
      </geometry>
      <material name="Grey">
        <color rgba="0.75 0.75 0.75 1.0"/>
      </material>
    </visual>
  </link>
  
  <joint name="j7_joint" type="revolute">
    <parent link="wam_link6"/>
    <child link="wam_link7"/>
    <origin rpy="1.57079632679 0 0" xyz="0.0 0.0 0.0"/>
    <axis xyz="0 0 1"/>
    <limit effort="30" lower="-2.2" upper="2.2" velocity="2.0"/>
    <!--  <safety_controller k_velocity="0.5"/>-->
    <dynamics damping="100"/>
  </joint>
   
  <!-- RIGHT HAND -->
  <link name="rhand_palm" />
  <link name="rhand_f1_base" >
  	<visual>
  		<geometry>
        	<mesh filename="robot/iri_wam/iri_wam_description/mesh/bh_link1.stl"/>
      	</geometry>
      	<origin rpy="0 0 3.1419" xyz="0 0 -0.034"/>
      	<material name="grey">
        	<color rgba="0.5 0.5 0.5 1"/>
      	</material>
  	</visual>
  </link>
  <link name="rhand_f1_proximal" >
  	<visual>
  		<geometry>
        	<mesh filename="robot/iri_wam/iri_wam_description/mesh/bh_link2.stl"/>
      	</geometry>
      	<origin rpy="-1.572 3.1419 0" xyz="0 0 0"/>
      	<material name="blue">
        	<color rgba="0.7 .7 0.7 1"/>
      	</material>
  	</visual>
  </link>
  <link name="rhand_f1_distal" >
  	<visual>
  		<geometry>
        	<mesh filename="robot/iri_wam/iri_wam_description/mesh/bh_link3.stl"/>
      	</geometry>
      	<origin rpy="-1.572 -1.57 0" xyz="0 0 0"/>
      	<material name="green">
        	<color rgba="0.7 .7 0.7 1"/>
      	</material>
  	</visual>
  </link>
  <link name="rhand_f1_tip" />
  <link name="rhand_f2_base" >
  	<visual>
  		<geometry>
        	<mesh filename="robot/iri_wam/iri_wam_description/mesh/bh_link1.stl"/>
      	</geometry>
      	<origin rpy="0 0 3.1419" xyz="0 0 -0.034"/>
      	<material name="grey">
        	<color rgba="0.5 0.5 0.5 1"/>
      	</material>
  	</visual>
  </link>
  <link name="rhand_f2_proximal" >
  	<visual>
  		<geometry>
        	<mesh filename="robot/iri_wam/iri_wam_description/mesh/bh_link2.stl"/>
      	</geometry>
      	<origin rpy="-1.572 3.1419 0" xyz="0 0 0"/>
      	<material name="blue">
        	<color rgba="0.7 .7 0.7 1"/>
      	</material>
  	</visual>
  </link>
  <link name="rhand_f2_distal" >
  	<visual>
  		<geometry>
        	<mesh filename="robot/iri_wam/iri_wam_description/mesh/bh_link3.stl"/>
      	</geometry>
      	<origin rpy="-1.57 -1.57 0" xyz="0 0 0"/>
      	<material name="green">
        	<color rgba="0.7 .7 0.7 1"/>
      	</material>
  	</visual>
  </link>
  <link name="rhand_f2_tip" />
  <link name="rhand_f3_base" />
  <link name="rhand_f3_proximal" >
  	<visual>
  		<geometry>
        	<mesh filename="robot/iri_wam/iri_wam_description/mesh/bh_link2.stl"/>
      	</geometry>
      	<origin rpy="1.57 0 0" xyz="0 0 0"/>
      	<material name="blue">
        	<color rgba="0.7 .7 0.7 1"/>
      	</material>
  	</visual>
  </link>
  <link name="rhand_f3_distal" >
  	<visual>
  		<geometry>
        	<mesh filename="robot/iri_wam/iri_wam_description/mesh/bh_link3.stl"/>
      	</geometry>
      	<origin rpy="1.57 -1.57 0" xyz="0 0 0"/>
      	<material name="green">
        	<color rgba="0.7 .7 0.7 1"/>
      	</material>
  	</visual>
  </link>
  <link name="rhand_f3_tip" />
  
  <joint name="rhand_palm_joint" type="fixed">
    <parent link="wam_link7"/>
    <child link="rhand_palm"/>
    <origin xyz="0 0 0.084" rpy="0 0 0" />
  </joint>
  
  <joint name="rhand_f1_rotation_joint" type="revolute">
    <parent link="rhand_palm"/>
    <child link="rhand_f1_base"/>
    <origin xyz="0 0.025 -0.01" rpy="0 0 0" />
    <axis xyz="0 0 -1" />
    <limit effort="1000.0" lower="0" upper="3.14159265" velocity="1.0"/>
  </joint>
  <joint name="rhand_f1_proximal_joint" type="revolute">
    <parent link="rhand_f1_base"/>
    <child link="rhand_f1_proximal"/>
    <origin xyz="-0.050 0 0" rpy="0 0.0429350996 0" />
    <axis xyz="0 1 0" />
    <limit effort="1000.0" lower="0" upper="2.44346095" velocity="1.0"/>
  </joint>
  <joint name="rhand_f1_distal_joint" type="revolute">
    <parent link="rhand_f1_proximal"/>
    <child link="rhand_f1_distal"/>
    <origin xyz="-0.070 0 0" rpy="0 -0.690452252 0" />
    <axis xyz="0 1 0" />
    <limit effort="1000.0" lower="0" upper="0.837758041" velocity="1.0"/>
    <mimic joint="rhand_f1_proximal_joint" multiplier="0.3333333" offset="0.0"/>
  </joint>
  <joint name="rhand_f1_tip_joint" type="fixed">
    <parent link="rhand_f1_distal"/>
    <child link="rhand_f1_tip"/>
    <origin xyz="0 0 0.056" rpy="0 0 0" />
  </joint>

  <joint name="rhand_f2_rotation_joint" type="revolute">
    <parent link="rhand_palm"/>
    <child link="rhand_f2_base"/>
    <origin xyz="0 -0.025 -0.01" rpy="0 0 0" />
    <axis xyz="0 0 1" />
    <limit effort="1000.0" lower="0" upper="3.14159265" velocity="1.0"/>
    <mimic joint="rhand_f1_rotation_joint" multiplier="1" offset="0"/>
  </joint>
  <joint name="rhand_f2_proximal_joint" type="revolute">
    <parent link="rhand_f2_base"/>
    <child link="rhand_f2_proximal"/>
    <origin xyz="-0.050 0 0" rpy="0 0.0429350996 0" />
    <axis xyz="0 1 0" />
    <limit effort="1000.0" lower="0" upper="2.44346095" velocity="1.0"/>
  </joint>
  <joint name="rhand_f2_distal_joint" type="revolute">
    <parent link="rhand_f2_proximal"/>
    <child link="rhand_f2_distal"/>
    <origin xyz="-0.070 0 0" rpy="0 -0.690452252 0" />
    <axis xyz="0 1 0" />
    <limit effort="1000.0" lower="0" upper="0.837758041" velocity="1.0"/>
    <mimic joint="rhand_f2_proximal_joint" multiplier="0.3333333" offset="0.0"/>
  </joint>
  <joint name="rhand_f2_tip_joint" type="fixed">
    <parent link="rhand_f2_distal"/>
    <child link="rhand_f2_tip"/>
    <origin xyz="0 0 0.056" rpy="0 0 0" />
  </joint>

  <joint name="rhand_f3_rotation_joint" type="fixed">
    <parent link="rhand_palm"/>
    <child link="rhand_f3_base"/>
    <origin xyz="0 0 -0.01" rpy="0 0 0" />
  </joint>
  <joint name="rhand_f3_proximal_joint" type="revolute">
    <parent link="rhand_f3_base"/>
    <child link="rhand_f3_proximal"/>
    <origin xyz="0.050 0 0" rpy="0 -0.0429350996 0" />
    <axis xyz="0 -1 0" />
    <limit effort="1000.0" lower="0" upper="2.44346095" velocity="1.0"/>
  </joint>
  <joint name="rhand_f3_distal_joint" type="revolute">
    <parent link="rhand_f3_proximal"/>
    <child link="rhand_f3_distal"/>
    <origin xyz="0.070 0 0" rpy="0 0.690452252 0" />
    <axis xyz="0 -1 0" />
    <limit effort="1000.0" lower="0" upper="0.837758041" velocity="1.0"/>
    <mimic joint="rhand_f3_proximal_joint" multiplier="0.3333333" offset="0.0"/>
  </joint>
  <joint name="rhand_f3_tip_joint" type="fixed">
    <parent link="rhand_f3_distal"/>
    <child link="rhand_f3_tip"/>
    <origin xyz="0 0 0.056" rpy="0 0 0" />
  </joint>
  
</robot>

